<robot
  name="Hobbit_BG_SLDASM">
  <link
    name="BaseLink">
    <inertial>
      <origin
        xyz="0.155508708861596 -0.0820749237889557 -0.105622612183798"
        rpy="0 0 0" />
      <mass
        value="7.85760449230508" />
      <inertia
        ixx="0.704154634061085"
        ixy="-0.00978226390042124"
        ixz="-0.00421276153343573"
        iyy="0.662337788738782"
        iyz="0.0178204373453035"
        izz="0.45220763495931" />
    </inertial>
    <visual>
      <origin
        xyz="0 0 0"
        rpy="0 0 0" />
      <geometry>
        <mesh
          filename="package://Hobbit_BG_SLDASM/meshes/BaseLink.STL" />
      </geometry>
      <material
        name="">
        <color
          rgba="0.752941176470588 0.752941176470588 0.752941176470588 1" />
      </material>
    </visual>
    <collision>
      <origin
        xyz="0 0 0"
        rpy="0 0 0" />
      <geometry>
        <mesh
          filename="package://Hobbit_BG_SLDASM/meshes/BaseLink.STL" />
      </geometry>
    </collision>
  </link>
  <link
    name="Link1">
    <inertial>
      <origin
        xyz="-1.7335E-07 0.00019321 0.06916"
        rpy="0 0 0" />
      <mass
        value="0.56765" />
      <inertia
        ixx="0.0010706"
        ixy="-2.0182E-08"
        ixz="2.6966E-08"
        iyy="0.0011007"
        iyz="4.2508E-06"
        izz="0.0011874" />
    </inertial>
    <visual>
      <origin
        xyz="0 0 0"
        rpy="0 0 0" />
      <geometry>
        <mesh
          filename="package://Hobbit_BG_SLDASM/meshes/Link1.STL" />
      </geometry>
      <material
        name="">
        <color
          rgba="0.75294 0.75294 0.75294 1" />
      </material>
    </visual>
    <collision>
      <origin
        xyz="0 0 0"
        rpy="0 0 0" />
      <geometry>
        <mesh
          filename="package://Hobbit_BG_SLDASM/meshes/Link1.STL" />
      </geometry>
    </collision>
  </link>
  <joint
    name="Joint1"
    type="revolute">
    <origin
      xyz="-0.10125 0 0"
      rpy="0 1.5708 0" />
    <parent
      link="BaseLink" />
    <child
      link="Link1" />
    <axis
      xyz="0 0 1" />
    <limit
      lower="-1.5708"
      upper="1.5708"
      effort="0"
      velocity="1" />
  </joint>
  <link
    name="Link2">
    <inertial>
      <origin
        xyz="0.056515 3.1375E-06 -0.00012859"
        rpy="0 0 0" />
      <mass
        value="0.78338" />
      <inertia
        ixx="0.00087714"
        ixy="3.5938E-07"
        ixz="-1.6051E-05"
        iyy="0.0052319"
        iyz="1.3604E-09"
        izz="0.0051309" />
    </inertial>
    <visual>
      <origin
        xyz="0 0 0"
        rpy="0 0 0" />
      <geometry>
        <mesh
          filename="package://Hobbit_BG_SLDASM/meshes/Link2.STL" />
      </geometry>
      <material
        name="">
        <color
          rgba="0.75294 0.75294 0.75294 1" />
      </material>
    </visual>
    <collision>
      <origin
        xyz="0 0 0"
        rpy="0 0 0" />
      <geometry>
        <mesh
          filename="package://Hobbit_BG_SLDASM/meshes/Link2.STL" />
      </geometry>
    </collision>
  </link>
  <joint
    name="Joint2"
    type="revolute">
    <origin
      xyz="0 0 0"
      rpy="3.1416 1.5708 0" />
    <parent
      link="Link1" />
    <child
      link="Link2" />
    <axis
      xyz="0 0 1" />
    <limit
      lower="-1.5708"
      upper="1.5708"
      effort="0"
      velocity="1" />
  </joint>
  <link
    name="Link3">
    <inertial>
      <origin
        xyz="-0.00931000412832889 -6.58946760915324E-05 5.42329501427156E-07"
        rpy="0 0 0" />
      <mass
        value="0.17684172153388" />
      <inertia
        ixx="0.000105253247705103"
        ixy="-1.07244591974433E-07"
        ixz="-9.00108478441004E-09"
        iyy="0.000134871769892199"
        iyz="1.33970645183285E-09"
        izz="0.000130675843789472" />
    </inertial>
    <visual>
      <origin
        xyz="0 0 0"
        rpy="0 0 0" />
      <geometry>
        <mesh
          filename="package://Hobbit_BG_SLDASM/meshes/Link3.STL" />
      </geometry>
      <material
        name="">
        <color
          rgba="0.752941176470588 0.752941176470588 0.752941176470588 1" />
      </material>
    </visual>
    <collision>
      <origin
        xyz="0 0 0"
        rpy="0 0 0" />
      <geometry>
        <mesh
          filename="package://Hobbit_BG_SLDASM/meshes/Link3.STL" />
      </geometry>
    </collision>
  </link>
  <joint
    name="Joint3"
    type="revolute">
    <origin
      xyz="0.25 0 0"
      rpy="1.5708 0 -3.1416" />
    <parent
      link="Link2" />
    <child
      link="Link3" />
    <axis
      xyz="0 0 -1" />
    <limit
      lower="-0.61"
      upper="2.0944"
      effort="0"
      velocity="1" />
  </joint>
  <link
    name="Link4">
    <inertial>
      <origin
        xyz="0.000472817986641846 -1.22697795517064E-05 -0.154129823843758"
        rpy="0 0 0" />
      <mass
        value="0.190545031539242" />
      <inertia
        ixx="0.000419492075610226"
        ixy="3.02821397089086E-09"
        ixz="-4.17349200648156E-06"
        iyy="0.000399356296042476"
        iyz="5.948932725389E-08"
        izz="9.30030166697615E-05" />
    </inertial>
    <visual>
      <origin
        xyz="0 0 0"
        rpy="0 0 0" />
      <geometry>
        <mesh
          filename="package://Hobbit_BG_SLDASM/meshes/Link4.STL" />
      </geometry>
      <material
        name="">
        <color
          rgba="0.752941176470588 0.752941176470588 0.752941176470588 1" />
      </material>
    </visual>
    <collision>
      <origin
        xyz="0 0 0"
        rpy="0 0 0" />
      <geometry>
        <mesh
          filename="package://Hobbit_BG_SLDASM/meshes/Link4.STL" />
      </geometry>
    </collision>
  </link>
  <joint
    name="Joint4"
    type="revolute">
    <origin
      xyz="0 0 0"
      rpy="-1.5708 0 -1.5708" />
    <parent
      link="Link3" />
    <child
      link="Link4" />
    <axis
      xyz="0 0 1" />
    <limit
      lower="-2.9671"
      upper="2.9671"
      effort="0"
      velocity="1" />
  </joint>
  <link
    name="Link5">
    <inertial>
      <origin
        xyz="-0.00930999568371604 6.58947718369332E-05 -5.16620754302009E-07"
        rpy="0 0 0" />
      <mass
        value="0.176841887951956" />
      <inertia
        ixx="0.000105253379030011"
        ixy="1.07244685583912E-07"
        ixz="9.04158534749876E-09"
        iyy="0.000134871914742637"
        iyz="1.34015989918887E-09"
        izz="0.000130675855017278" />
    </inertial>
    <visual>
      <origin
        xyz="0 0 0"
        rpy="0 0 0" />
      <geometry>
        <mesh
          filename="package://Hobbit_BG_SLDASM/meshes/Link5.STL" />
      </geometry>
      <material
        name="">
        <color
          rgba="0.752941176470588 0.752941176470588 0.752941176470588 1" />
      </material>
    </visual>
    <collision>
      <origin
        xyz="0 0 0"
        rpy="0 0 0" />
      <geometry>
        <mesh
          filename="package://Hobbit_BG_SLDASM/meshes/Link5.STL" />
      </geometry>
    </collision>
  </link>
  <joint
    name="Joint5"
    type="revolute">
    <origin
      xyz="0 0 -0.235"
      rpy="1.5708 -1.5708 0" />
    <parent
      link="Link4" />
    <child
      link="Link5" />
    <axis
      xyz="0 0 -1" />
    <limit
      lower="-0.8727"
      upper="2.2689"
      effort="0"
      velocity="1" />
  </joint>
  <link
    name="Link6">
    <inertial>
      <origin
        xyz="-2.74875008970725E-07 -2.25671667287812E-08 0.153638607246516"
        rpy="0 0 0" />
      <mass
        value="0.133479113104941" />
      <inertia
        ixx="0.000373762082490115"
        ixy="-4.73766126479978E-08"
        ixz="-1.25333130583937E-10"
        iyy="0.000375770131010094"
        iyz="-1.5342530358527E-10"
        izz="2.9252379948062E-05" />
    </inertial>
    <visual>
      <origin
        xyz="0 0 0"
        rpy="0 0 0" />
      <geometry>
        <mesh
          filename="package://Hobbit_BG_SLDASM/meshes/Link6.STL" />
      </geometry>
      <material
        name="">
        <color
          rgba="0.752941176470588 0.752941176470588 0.752941176470588 1" />
      </material>
    </visual>
    <collision>
      <origin
        xyz="0 0 0"
        rpy="0 0 0" />
      <geometry>
        <mesh
          filename="package://Hobbit_BG_SLDASM/meshes/Link6.STL" />
      </geometry>
    </collision>
  </link>
  <joint
    name="Joint6"
    type="revolute">
    <origin
      xyz="0 0 0"
      rpy="3.1416 1.5708 0" />
    <parent
      link="Link5" />
    <child
      link="Link6" />
    <axis
      xyz="0 0 1" />
    <limit
      lower="-2.9409"
      upper="2.9409"
      effort="0"
      velocity="1" />
  </joint>
  <link
    name="Link_Jaw1">
    <inertial>
      <origin
        xyz="0.0500857180092174 0.0100661008624554 3.73625772053497E-08"
        rpy="0 0 0" />
      <mass
        value="0.0317463301873309" />
      <inertia
        ixx="5.74408948710455E-06"
        ixy="-4.38590962307411E-06"
        ixz="3.94684885862703E-11"
        iyy="5.08173989682709E-05"
        iyz="-6.51863547190818E-12"
        izz="5.38160836229214E-05" />
    </inertial>
    <visual>
      <origin
        xyz="0 0 0"
        rpy="0 0 0" />
      <geometry>
        <mesh
          filename="package://Hobbit_BG_SLDASM/meshes/Link_Jaw1.STL" />
      </geometry>
      <material
        name="">
        <color
          rgba="0.752941176470588 0.752941176470588 0.752941176470588 1" />
      </material>
    </visual>
    <collision>
      <origin
        xyz="0 0 0"
        rpy="0 0 0" />
      <geometry>
        <mesh
          filename="package://Hobbit_BG_SLDASM/meshes/Link_Jaw1.STL" />
      </geometry>
    </collision>
  </link>
  <joint
    name="Joint_Jaw1"
    type="revolute">
    <origin
      xyz="0 -0.004 0.21335"
      rpy="3.1416 -1.5708 0" />
    <parent
      link="Link6" />
    <child
      link="Link_Jaw1" />
    <axis
      xyz="0 0 1" />
    <limit
      lower="0"
      upper="0.34907"
      effort="0"
      velocity="1" />
  </joint>
  <link
    name="Link_Jaw2">
    <inertial>
      <origin
        xyz="0.050098 0.010007 3.7629E-08"
        rpy="0 0 0" />
      <mass
        value="0.031746" />
      <inertia
        ixx="5.7546E-06"
        ixy="-4.4395E-06"
        ixz="3.956E-11"
        iyy="5.0807E-05"
        iyz="-6.6007E-12"
        izz="5.3816E-05" />
    </inertial>
    <visual>
      <origin
        xyz="0 0 0"
        rpy="0 0 0" />
      <geometry>
        <mesh
          filename="package://Hobbit_BG_SLDASM/meshes/Link_Jaw2.STL" />
      </geometry>
      <material
        name="">
        <color
          rgba="0.75294 0.75294 0.75294 1" />
      </material>
    </visual>
    <collision>
      <origin
        xyz="0 0 0"
        rpy="0 0 0" />
      <geometry>
        <mesh
          filename="package://Hobbit_BG_SLDASM/meshes/Link_Jaw2.STL" />
      </geometry>
    </collision>
  </link>
  <joint
    name="Joint_Jaw2"
    type="revolute">
    <origin
      xyz="0 0.004 0.21335"
      rpy="0 -1.5708 0" />
    <parent
      link="Link6" />
    <child
      link="Link_Jaw2" />
    <axis
      xyz="0 0 1" />
    <limit
      lower="0"
      upper="0.34907"
      effort="0"
      velocity="1" />
  </joint>
</robot>
